Workbook

Sheet Consolidated
B1: Weightage | C1: 1 | D1: 2 | E1: 3 | F1: 4 | G1: 5
A2: Environment | B2: 40 | C2: =(E8+E19)*($B$2/100) -> 11.28 | D2: =(G8+G19)*($B$2/100) -> 4.08 | E2: =(I8+I19)*($B$2/100) -> 6.32 | F2: =(K8+K19)*($B$2/100) -> 4.8 | G2: =(M8+M19)*($B$2/100) -> 14
A3: Social | B3: 30 | C3: =(E27+E42)*($B$3/100) -> 7.26 | D3: =(G27+G42)*($B$3/100) -> 1.77 | E3: =(I27+I42)*($B$3/100) -> 2.97 | F3: =(K27+K42)*($B$3/100) -> 1.2 | G3: =(M27+M42)*($B$3/100) -> 4.5
A4: Governance | B4: 30 | C4: =(E48+E55)*($B$4/100) -> 4.5 | D4: =(G48+G55)*($B$4/100) -> 4.86 | E4: =(I48+I55)*($B$4/100) -> 2.4 | F4: =(K48+K55)*($B$4/100) -> 4.98 | G4: =(M48+M55)*($B$4/100) -> 12
A5: Total | B5: =SUM(B2:B4) -> 100 | C5: =SUM(C2:C4) -> 23.04 | D5: =SUM(D2:D4) -> 10.71 | E5: =SUM(E2:E4) -> 11.69 | F5: =SUM(F2:F4) -> 10.98 | G5: =SUM(G2:G4) -> 30.5
A7: Environment | B7: 1 | C7: Management system training (20 Points) | D7: 1 | F7: 2 | H7: 3 | J7: 4 | L7: 5 | N7: ESG Score (%)
A8: Environment | B8: 1.1 | C8: Does the facility have a management system in place, or is it developing one, to assess environmental risks associated with production? | D8: ='1'!G8:G9 -> 10 | E8: ='1'!H8:H17 -> 28.2 | F8: ='2'!G8:G9 -> 5 | G8: ='2'!H8:H17 -> 4.2 | H8: ='3'!G8:G9 -> 10 | I8: ='3'!H8:H17 -> 8 | J8: ='4'!G8:G9 -> 5 | K8: ='4'!H8:H17 -> 8.4 | L8: ='5'!G8:G9 -> 10 | M8: ='5'!H8:H17 -> 20 | N8: 10 | O8: 20
A9: Environment | C9: If yes, Specify certification ?
A10: Environment | B10: 1.2 | C10: Is the facility management system in compliance with applicable environmental laws and regulations? | D10: ='1'!G10 -> 0 | F10: ='2'!G10 -> 0 | H10: ='3'!G10 -> 0 | J10: ='4'!G10 -> 0 | L10: ='5'!G10 -> 20 | N10: 20
A11: Environment | B11: 1.3 | C11: Does the facility hold the necessary valid license(s) or permit(s) to operate ? | D11: ='1'!G11 -> 15 | F11: ='2'!G11 -> 8 | H11: ='3'!G11 -> 15 | J11: ='4'!G11 -> 20 | L11: ='5'!G11 -> 20 | N11: 20
A12: Environment | B12: 1.3.1 | C12: Has the facility been levied with fines, penalty, warning or prosecution in past ? Specify year and details | D12: ='1'!G12 -> 10 | F12: ='2'!G12 -> 0 | H12: ='3'!G12 -> 0 | J12: ='4'!G12 -> 0 | L12: ='5'!G12 -> 10 | N12: 10
A13: Environment | B13: `1.4 | C13: Are environmental policies, practices, and expectations communicated to all employees and suppliers in local or appropriate languages? | D13: ='1'!G13 -> 0 | F13: ='2'!G13 -> 5 | H13: ='3'!G13 -> 0 | J13: ='4'!G13 -> 5 | L13: ='5'!G13 -> 10 | N13: 10
A14: Environment | B14: 1.6 | C14: Do you have a training Awareness Programs of employess for awareness related to Environment? Frequency | D14: ='1'!G14 -> 5 | F14: ='2'!G14 -> 0 | H14: ='3'!G14 -> 5 | J14: ='4'!G14 -> 3 | L14: ='5'!G14 -> 10 | N14: 10
A15: Environment | B15: 1.7 | C15: Does the facility have established environmental targets and objectives to improve environmental performance? | D15: ='1'!G15 -> 0 | F15: ='2'!G15 -> 0 | H15: ='3'!G15 -> 10 | J15: ='4'!G15 -> 0 | L15: ='5'!G15 -> 10 | N15: 10
A16: Environment | B16: 1.8 | C16: Does the facility review its environmental performance? If yes How often | D16: ='1'!G16 -> 7 | F16: ='2'!G16 -> 3 | H16: ='3'!G16 -> 0 | J16: ='4'!G16 -> 9 | L16: ='5'!G16 -> 10 | N16: 10
A17: Environment
A18: Environment | B18: 2. Greenhouse Gas (GHG) Emissions and Energy Usage
A19: Environment | B19: 2.1 | C19: Does the facility report GHG emissions and climate change strategy to the Carbon Disclosure Project (CDP) or publicly disclose an equivalent amount and type of information on an annual basis? | D19: ='1'!G19 -> 0 | E19: ='1'!H19:H24 -> 0 | F19: ='2'!G19 -> 15 | G19: ='2'!H19:H24 -> 6 | H19: ='3'!G19 -> 15 | I19: ='3'!H19:H24 -> 7.8 | J19: ='4'!G19 -> 0 | K19: ='4'!H19:H24 -> 3.6 | L19: ='5'!G19 -> 30 | M19: ='5'!H19:H24 -> 15 | N19: 30 | O19: 15
A20: Environment | B20: 2.2 | C20: What is the frequency of monitoring, tracking energy consumption and conducting onsite energy audits of the facility? | D20: ='1'!G20 -> 0 | F20: ='2'!G20 -> 15 | H20: ='3'!G20 -> 12 | J20: ='4'!G20 -> 9 | L20: ='5'!G20 -> 15 | N20: 15
A21: Environment | B21: 2.3 | C21: Specify programs and procedures in place to reduce the use of energy | D21: ='1'!G21 -> 0 | F21: ='2'!G21 -> 0 | H21: ='3'!G21 -> 0 | J21: ='4'!G21 -> 0 | L21: ='5'!G21 -> 20 | N21: 20
A22: Environment | B22: 2.4 | C22: Specify the GHG emissions targets for the facility if any ? | D22: ='1'!G22 -> 0 | F22: ='2'!G22 -> 0 | H22: ='3'!G22 -> 10 | J22: ='4'!G22 -> 0 | L22: ='5'!G22 -> 10 | N22: 10
A23: Environment | B23: 2.5 | C23: What is the total annual GHG emissions in the most recent year measured (enter in total metric tons CO2e)? | D23: ='1'!G23 -> 0 | F23: ='2'!G23 -> 10 | H23: ='3'!G23 -> 0 | J23: ='4'!G23 -> 0 | L23: ='5'!G23 -> 10 | N23: 10
A24: Environment | B24: 2.6 | C24: Does the facility have set goals and targets in relation to energy efficiency? | D24: ='1'!G24 -> 0 | F24: ='2'!G24 -> 0 | H24: ='3'!G24 -> 15 | J24: ='4'!G24 -> 15 | L24: ='5'!G24 -> 15 | N24: 15
L25: ='5'!G25 -> 0
A26: Social | B26: 1 | C26: Employment | L26: ='5'!G26 -> 0
A27: Social | B27: 1.1 | C27: Total number of new employees hired in the indicated period. | D27: ='1'!G27 -> 0 | E27: ='1'!H27:H40 -> 18.2 | F27: ='2'!G27 -> 6 | G27: ='2'!H27:H40 -> 3.4 | H27: ='3'!G27 -> 8 | I27: ='3'!H27:H40 -> 5.9 | J27: ='4'!G27 -> 10 | K27: ='4'!H27:H40 -> 4 | L27: ='5'!G27 -> 10 | M27: ='5'!H27:H40 -> 10 | N27: 10 | O27: 10
A28: Social | B28: 1.2 | C28: Number of new employees females hired for the indicated period | D28: ='1'!G28 -> 6 | F28: ='2'!G28 -> 6 | H28: ='3'!G28 -> 8 | J28: ='4'!G28 -> 8 | L28: ='5'!G28 -> 10 | N28: 10
A29: Social | B29: 1.3 | C29: Number of new employees males hired for the indicated period | D29: ='1'!G29 -> 8 | F29: ='2'!G29 -> 0 | H29: ='3'!G29 -> 6 | J29: ='4'!G29 -> 8 | L29: ='5'!G29 -> 10 | N29: 10
A30: Social | B30: 1.4 | C30: Number of third gender employees hired for the indicated period | D30: ='1'!G30 -> 0 | F30: ='2'!G30 -> 0 | H30: ='3'!G30 -> 8 | J30: ='4'!G30 -> 0 | L30: ='5'!G30 -> 10 | N30: 10
A31: Social | B31: 1.5 | C31: Rate of tunrnover of the employees for the reporting period (Numbers of employees left/ total strength for the period *100) | D31: ='1'!G31 -> 6 | F31: ='2'!G31 -> 2 | H31: ='3'!G31 -> 6 | J31: ='4'!G31 -> 2 | L31: ='5'!G31 -> 10 | N31: 10
A32: Social | B32: 1.6 | C32: Does Company provides benefits to its full time employees | D32: ='1'!G32 -> 2 | F32: ='2'!G32 -> 10 | H32: ='3'!G32 -> 5 | J32: ='4'!G32 -> 0 | L32: ='5'!G32 -> 20 | N32: 20 (5 each point)
A33: Social | C33: If Yes, Select the options relevant
A34: Social | C34: Health care
A35: Social | C35: Life insurance
A36: Social | C36: Stock ownership
A37: Social | C37: Parental leave
A38: Social | B38: 1.7 | C38: Ratio of contractual to non contractual workforce | D38: ='1'!G38 -> 2 | F38: ='2'!G38 -> 6 | H38: ='3'!G38 -> 10 | J38: ='4'!G38 -> 0 | L38: ='5'!G38 -> 10 | N38: 10
A39: Social | B39: 1.8 | C39: Ratio of permanent employees females to male (time sensitive- yearly information ) | D39: ='1'!G39 -> 2 | F39: ='2'!G39 -> 2 | H39: ='3'!G39 -> 4 | J39: ='4'!G39 -> 6 | L39: ='5'!G39 -> 10 | N39: 10
A40: Social | B40: 1.9 | C40: Minimum number of weeks’ notice typically provided to employees and their representatives in advance for operational changes | D40: ='1'!G40 -> 0 | F40: ='2'!G40 -> 2 | H40: ='3'!G40 -> 4 | J40: ='4'!G40 -> 6 | L40: ='5'!G40 -> 10 | N40: 10
A41: Social | B41: 2 | C41: Child Labour | L41: ='5'!G41 -> 0
...

Sheet 1
A2: Environment | B2: 40 | C2: =(H8+H19)*(B2/100) -> 11.28
A3: Social | B3: 30 | C3: =(H27+H42)*(B3/100) -> 7.26
A4: Governance | B4: 30 | C4: =(H48+H55)*(B4/100) -> 4.5
A5: Total | B5: =SUM(B2:B4) -> 100 | C5: =SUM(C2:C4) -> 23.04
A7: Environment | B7: 1 | C7: Management system training (20 Points) | D7: Answers | E7: Responses | F7: Supporting documents | I7: ESG Score (%)
A8: Environment | B8: 1.1 | C8: Does the facility have a management system in place, or is it developing one, to assess environmental risks associated with production? | D8: Yes/No | E8: Yes | G8: =IF(E8="Yes",5,0)+IF(E9="Yes",5,0) -> 10 | H8: =SUM(G8:G17)*(J8/100) -> 28.2 | I8: 10 | J8: 60
A9: Environment | C9: If yes, Specify certification ? | D9: ISO 14001, RC 14001, or EMAS | E9: Yes | F9: Upload document
A10: Environment | B10: 1.2 | C10: Is the facility management system in compliance with applicable environmental laws and regulations? | D10: Drop down for the same to be provided (Multi select) | F10: Number of ticks/selection | G10: =IF(E10=0,0,IF(E10<3,8,IF(E10<5,15,IF(E10>5,20)))) -> 0 | I10: 20 | M10: Dropdown data source missing
A11: Environment | B11: 1.3 | C11: Does the facility hold the necessary valid license(s) or permit(s) to operate ? | D11: License(s) or Permit(s): Air emissions Storage or use of hazardous substances Waste water management Waste issues | E11: 4 | F11: Fines, prosecution, or warnings by regulators: Air emissions Storage or use of hazardous substances Preventing soil & groundwater contamination Wastewater management Waste issues | G11: =IF(E11=0,0,IF(E11<3,8,IF(E11<5,15,IF(E11>5,20)))) -> 15 | I11: 20
A12: Environment | B12: 1.3.1 | C12: Has the facility been levied with fines, penalty, warning or prosecution in past ? Specify year and details | D12: Yes/No | E12: No | G12: =IF(E12="Yes",0,10) -> 10 | I12: 10
A13: Environment | B13: `1.4 | C13: Are environmental policies, practices, and expectations communicated to all employees and suppliers in local or appropriate languages? | D13: Yes/No Provide proof (Uploads) | E13: No | F13: No | G13: =IF(E13="Yes",5,0)+IF(F13="Yes",5,0) -> 0 | I13: 10
A14: Environment | B14: 1.6 | C14: Do you have a training Awareness Programs of employess for awareness related to Environment? Frequency | D14: Monthly, Quarterly, Half yearly, Annual | E14: Yes | G14: =IF(E14="Yes",5,0)+(IF(F14="Monthly",5,IF(F14="Quarterly",4,IF(F14="Half Yearly",3,IF(F14="Annual",2,0))))) -> 5 | I14: 10
A15: Environment | B15: 1.7 | C15: Does the facility have established environmental targets and objectives to improve environmental performance? | D15: Yes/No | E15: No | F15: If Yes, Specify | G15: =IF(E15="Yes",10,0) -> 0 | I15: 10 | M15: Is specify details will be text field ? (Wiziwig)
A16: Environment | B16: 1.8 | C16: Does the facility review its environmental performance? If yes How often | D16: Monthly, Quarterly, Half yearly, Annual | E16: Yes | F16: Annual | G16: =IF(E16="Yes",5,0)+(IF(F16="Monthly",5,IF(F16="Quarterly",4,IF(F16="Half Yearly",3,IF(F16="Annual",2,0))))) -> 7 | I16: 10
A17: Environment
A18: Environment | B18: 2. Greenhouse Gas (GHG) Emissions and Energy Usage
A19: Environment | B19: 2.1 | C19: Does the facility report GHG emissions and climate change strategy to the Carbon Disclosure Project (CDP) or publicly disclose an equivalent amount and type of information on an annual basis? | D19: Yes/No Provide proof (Uploads) | E19: No | F19: No | G19: =IF(E19="Yes",15,0)+IF(F19="Yes",15,0) -> 0 | H19: =SUM(G19:G24)*(J19/100) -> 0 | I19: 30 | J19: 40
A20: Environment | B20: 2.2 | C20: What is the frequency of monitoring, tracking energy consumption and conducting onsite energy audits of the facility? | D20: Monthly, Quarterly, Half yearly, Annual | G20: =(IF(F20="Monthly",15,IF(F20="Quarterly",12,IF(F20="Half Yearly",9,IF(F20="Annual",6,0))))) -> 0 | I20: 15
A21: Environment | B21: 2.3 | C21: Specify programs and procedures in place to reduce the use of energy | D21: Subjective | F21: Number of ticks/selection | G21: =IF(E21=0,0,IF(E21<3,8,IF(E21<5,15,IF(E21>5,20)))) -> 0 | I21: 20 | M21: What will be the input type (Tags)
A22: Environment | B22: 2.4 | C22: Specify the GHG emissions targets for the facility if any ? | D22: Numeric Response | E22: No | F22: Numeric entry | G22: =IF(E22="Yes",10,0) -> 0 | I22: 10
A23: Environment | B23: 2.5 | C23: What is the total annual GHG emissions in the most recent year measured (enter in total metric tons CO2e)? | D23: Numeric Response | E23: No | F23: Numeric entry | G23: =IF(E23="Yes",10,0) -> 0 | I23: 10
A24: Environment | B24: 2.6 | C24: Does the facility have set goals and targets in relation to energy efficiency? | D24: Yes/No | E24: No | G24: =IF(E24="Yes",15,0) -> 0 | I24: 15
A26: Social | B26: 1 | C26: Employment
A27: Social | B27: 1.1 | C27: Total number of new employees hired in the indicated period. | D27: Numeric response | E27: 0 | F27: Numeric | G27: =IF(E27=0,0,IF(E27<5,6,IF(E27<10,8,IF(E27>10,10)))) -> 0 | H27: =SUM(G27:G40)*(J27/100) -> 18.2 | I27: 10 | J27: 70
A28: Social | B28: 1.2 | C28: Number of new employees females hired for the indicated period | D28: Numeric response | E28: 1 | F28: Numeric | G28: =IF(E28=0,0,IF(E28<5,6,IF(E28<10,8,IF(E28>10,10)))) -> 6 | I28: 10
A29: Social | B29: 1.3 | C29: Number of new employees males hired for the indicated period | D29: Numeric response | E29: 5 | F29: Numeric | G29: =IF(E29=0,0,IF(E29<5,6,IF(E29<10,8,IF(E29>10,10)))) -> 8 | I29: 10
A30: Social | B30: 1.4 | C30: Number of third gender employees hired for the indicated period | D30: Numeric response | E30: 0 | F30: Numeric | G30: =IF(E30=0,0,IF(E30<5,6,IF(E30<10,8,IF(E30>10,10)))) -> 0 | I30: 10
A31: Social | B31: 1.5 | C31: Rate of tunrnover of the employees for the reporting period (Numbers of employees left/ total strength for the period *100) | D31: Numeric response | E31: 5 | G31: =IF(E31=0,0,IF(E31<5,10,IF(E31<10,6,IF(E31>10,2)))) -> 6 | I31: 10
A32: Social | B32: 1.6 | C32: Does Company provides benefits to its full time employees | D32: Yes/No | E32: Yes | F32: If yes provide proof | G32: =IF(E32="Yes",0,0)+IF(E34="Yes",2,0)+IF(E35="Yes",2,0)+IF(E36="Yes",2,0)+IF(E37="Yes",2,0)+IF(F34="Yes",3,0)+IF(F35="Yes",3,0)+IF(F36="Yes",3,0)+IF(F37="Yes",3,0) -> 2 | I32: 20 (5 each point)
A33: Social | C33: If Yes, Select the options relevant
A34: Social | C34: Health care | D34: Yes/No | E34: No | F34: No
A35: Social | C35: Life insurance | D35: Yes/No | E35: No | F35: No
A36: Social | C36: Stock ownership | D36: Yes/No | E36: No | F36: No
A37: Social | C37: Parental leave | D37: Yes/No | E37: Yes | F37: No
A38: Social | B38: 1.7 | C38: Ratio of contractual to non contractual workforce | D38: Numeric response | E38: 15 | G38: =IF(E38=0,0,IF(E38<5,10,IF(E38<10,6,IF(E38>10,2)))) -> 2 | I38: 10
A39: Social | B39: 1.8 | C39: Ratio of permanent employees females to male (time sensitive- yearly information ) | D39: Numeric response | E39: 15 | G39: =IF(E39=0,0,IF(E39<25,2,IF(E39<40,4,IF(E39<55,6,IF(E39<70,8,IF(E39>70,10)))))) -> 2 | I39: 10
A40: Social | B40: 1.9 | C40: Minimum number of weeks’ notice typically provided to employees and their representatives in advance for operational changes | D40: Numeric response | E40: 0 | G40: =IF(E40=0,0,IF(E40<15,2,IF(E40<30,4,IF(E40<45,6,IF(E40<60,8,IF(E40>60,10,)))))) -> 0 | I40: 10
A41: Social | B41: 2 | C41: Child Labour
A42: Social | B42: 2.1 | C42: Does the organisation engage person for work below 18 years of age | D42: Yes/No | E42: No | G42: =IF(E42="No",20,0) -> 20 | H42: =SUM(G42:G45)*(J42/100) -> 6 | I42: 20 | J42: 30
A43: Social | B43: 2.2 | C43: Does organisation has any policy against child labour and remediation plan in case anyone found? | D43: Yes/No Upload Policy | E43: No | F43: No | G43: =IF(E43="Yes",15,0)+IF(F43="Yes",15,0) -> 0 | I43: 30
...

Sheet 2
A2: Environment | B2: 40 | C2: =(H8+H19)*(B2/100) -> 4.08
A3: Social | B3: 30 | C3: =(H27+H42)*(B3/100) -> 1.77
A4: Governance | B4: 30 | C4: =(H48+H55)*(B4/100) -> 4.86
A5: Total | B5: =SUM(B2:B4) -> 100 | C5: =SUM(C2:C4) -> 10.71
A7: Environment | B7: 1 | C7: Management system training (20 Points) | D7: Answers | E7: Responses | F7: Supporting documents | I7: ESG Score (%)
A8: Environment | B8: 1.1 | C8: Does the facility have a management system in place, or is it developing one, to assess environmental risks associated with production? | D8: Yes/No | E8: Yes | G8: =IF(E8="Yes",5,0)+IF(E9="Yes",5,0) -> 5 | H8: =SUM(G8:G17)*(J8/100) -> 4.2 | I8: 10 | J8: 20
A9: Environment | C9: If yes, Specify certification ? | D9: ISO 14001, RC 14001, or EMAS | E9: No | F9: Upload document
A10: Environment | B10: 1.2 | C10: Is the facility management system in compliance with applicable environmental laws and regulations? | D10: Drop down for the same to be provided (Multi select) | F10: Number of ticks/selection | G10: =IF(E10=0,0,IF(E10<3,8,IF(E10<5,15,IF(E10>5,20)))) -> 0 | I10: 20
A11: Environment | B11: 1.3 | C11: Does the facility hold the necessary valid license(s) or permit(s) to operate ? | D11: License(s) or Permit(s): Air emissions Storage or use of hazardous substances Waste water management Waste issues | E11: 2 | F11: Fines, prosecution, or warnings by regulators: Air emissions Storage or use of hazardous substances Preventing soil & groundwater contamination Wastewater management Waste issues | G11: =IF(E11=0,0,IF(E11<3,8,IF(E11<5,15,IF(E11>5,20)))) -> 8 | I11: 20
A12: Environment | B12: 1.3.1 | C12: Has the facility been levied with fines, penalty, warning or prosecution in past ? Specify year and details | D12: Yes/No | E12: Yes | G12: =IF(E12="Yes",0,10) -> 0 | I12: 10
A13: Environment | B13: `1.4 | C13: Are environmental policies, practices, and expectations communicated to all employees and suppliers in local or appropriate languages? | D13: Yes/No Provide proof (Uploads) | E13: Yes | F13: No | G13: =IF(E13="Yes",5,0)+IF(F13="Yes",5,0) -> 5 | I13: 10
A14: Environment | B14: 1.6 | C14: Do you have a training Awareness Programs of employess for awareness related to Environment? Frequency | D14: Monthly, Quarterly, Half yearly, Annual | E14: No | G14: =IF(E14="Yes",5,0)+(IF(F14="Monthly",5,IF(F14="Quarterly",4,IF(F14="Half Yearly",3,IF(F14="Annual",2,0))))) -> 0 | I14: 10
A15: Environment | B15: 1.7 | C15: Does the facility have established environmental targets and objectives to improve environmental performance? | D15: Yes/No | E15: No | F15: If Yes, Specify | G15: =IF(E15="Yes",10,0) -> 0 | I15: 10
A16: Environment | B16: 1.8 | C16: Does the facility review its environmental performance? If yes How often | D16: Monthly, Quarterly, Half yearly, Annual | E16: No | F16: Half Yearly | G16: =IF(E16="Yes",5,0)+(IF(F16="Monthly",5,IF(F16="Quarterly",4,IF(F16="Half Yearly",3,IF(F16="Annual",2,0))))) -> 3 | I16: 10
A17: Environment
A18: Environment | B18: 2. Greenhouse Gas (GHG) Emissions and Energy Usage
A19: Environment | B19: 2.1 | C19: Does the facility report GHG emissions and climate change strategy to the Carbon Disclosure Project (CDP) or publicly disclose an equivalent amount and type of information on an annual basis? | D19: Yes/No Provide proof (Uploads) | E19: Yes | F19: No | G19: =IF(E19="Yes",15,0)+IF(F19="Yes",15,0) -> 15 | H19: =SUM(G19:G24)*(J19/100) -> 6 | I19: 30 | J19: 15
A20: Environment | B20: 2.2 | C20: What is the frequency of monitoring, tracking energy consumption and conducting onsite energy audits of the facility? | D20: Monthly, Quarterly, Half yearly, Annual | F20: Monthly | G20: =(IF(F20="Monthly",15,IF(F20="Quarterly",12,IF(F20="Half Yearly",9,IF(F20="Annual",6,0))))) -> 15 | I20: 15
A21: Environment | B21: 2.3 | C21: Specify programs and procedures in place to reduce the use of energy | D21: Subjective | F21: Number of ticks/selection | G21: =IF(E21=0,0,IF(E21<3,8,IF(E21<5,15,IF(E21>5,20)))) -> 0 | I21: 20
A22: Environment | B22: 2.4 | C22: Specify the GHG emissions targets for the facility if any ? | D22: Numeric Response | E22: No | F22: Numeric entry | G22: =IF(E22="Yes",10,0) -> 0 | I22: 10
A23: Environment | B23: 2.5 | C23: What is the total annual GHG emissions in the most recent year measured (enter in total metric tons CO2e)? | D23: Numeric Response | E23: Yes | F23: Numeric entry | G23: =IF(E23="Yes",10,0) -> 10 | I23: 10
A24: Environment | B24: 2.6 | C24: Does the facility have set goals and targets in relation to energy efficiency? | D24: Yes/No | E24: No | G24: =IF(E24="Yes",15,0) -> 0 | I24: 15
A26: Social | B26: 1 | C26: Employment
A27: Social | B27: 1.1 | C27: Total number of new employees hired in the indicated period. | D27: Numeric response | E27: 3 | F27: Numeric | G27: =IF(E27=0,0,IF(E27<5,6,IF(E27<10,8,IF(E27>10,10)))) -> 6 | H27: =SUM(G27:G40)*(J27/100) -> 3.4 | I27: 10 | J27: 10
A28: Social | B28: 1.2 | C28: Number of new employees females hired for the indicated period | D28: Numeric response | E28: 3 | F28: Numeric | G28: =IF(E28=0,0,IF(E28<5,6,IF(E28<10,8,IF(E28>10,10)))) -> 6 | I28: 10
A29: Social | B29: 1.3 | C29: Number of new employees males hired for the indicated period | D29: Numeric response | E29: 0 | F29: Numeric | G29: =IF(E29=0,0,IF(E29<5,6,IF(E29<10,8,IF(E29>10,10)))) -> 0 | I29: 10
A30: Social | B30: 1.4 | C30: Number of third gender employees hired for the indicated period | D30: Numeric response | E30: 0 | F30: Numeric | G30: =IF(E30=0,0,IF(E30<5,6,IF(E30<10,8,IF(E30>10,10)))) -> 0 | I30: 10
A31: Social | B31: 1.5 | C31: Rate of tunrnover of the employees for the reporting period (Numbers of employees left/ total strength for the period *100) | D31: Numeric response | E31: 110 | G31: =IF(E31=0,0,IF(E31<5,10,IF(E31<10,6,IF(E31>10,2)))) -> 2 | I31: 10
A32: Social | B32: 1.6 | C32: Does Company provides benefits to its full time employees | D32: Yes/No | E32: Yes | F32: If yes provide proof | G32: =IF(E32="Yes",0,0)+IF(E34="Yes",2,0)+IF(E35="Yes",2,0)+IF(E36="Yes",2,0)+IF(E37="Yes",2,0)+IF(F34="Yes",3,0)+IF(F35="Yes",3,0)+IF(F36="Yes",3,0)+IF(F37="Yes",3,0) -> 10 | I32: 20 (5 each point)
A33: Social | C33: If Yes, Select the options relevant
A34: Social | C34: Health care | D34: Yes/No | E34: Yes | F34: Yes
A35: Social | C35: Life insurance | D35: Yes/No | E35: Yes | F35: Yes
A36: Social | C36: Stock ownership | D36: Yes/No | E36: No | F36: No
A37: Social | C37: Parental leave | D37: Yes/No | E37: No | F37: No
A38: Social | B38: 1.7 | C38: Ratio of contractual to non contractual workforce | D38: Numeric response | E38: 7 | G38: =IF(E38=0,0,IF(E38<5,10,IF(E38<10,6,IF(E38>10,2)))) -> 6 | I38: 10
A39: Social | B39: 1.8 | C39: Ratio of permanent employees females to male (time sensitive- yearly information ) | D39: Numeric response | E39: 20 | G39: =IF(E39=0,0,IF(E39<25,2,IF(E39<40,4,IF(E39<55,6,IF(E39<70,8,IF(E39>70,10)))))) -> 2 | I39: 10
A40: Social | B40: 1.9 | C40: Minimum number of weeks’ notice typically provided to employees and their representatives in advance for operational changes | D40: Numeric response | E40: 1 | G40: =IF(E40=0,0,IF(E40<15,2,IF(E40<30,4,IF(E40<45,6,IF(E40<60,8,IF(E40>60,10,)))))) -> 2 | I40: 10
A41: Social | B41: 2 | C41: Child Labour
A42: Social | B42: 2.1 | C42: Does the organisation engage person for work below 18 years of age | D42: Yes/No | E42: Yes | G42: =IF(E42="No",20,0) -> 0 | H42: =SUM(G42:G45)*(J42/100) -> 2.5 | I42: 20 | J42: 5
A43: Social | B43: 2.2 | C43: Does organisation has any policy against child labour and remediation plan in case anyone found? | D43: Yes/No Upload Policy | E43: Yes | F43: Yes | G43: =IF(E43="Yes",15,0)+IF(F43="Yes",15,0) -> 30 | I43: 30
...

Sheet 3
A2: Environment | B2: 40 | C2: =(H8+H19)*(B2/100) -> 6.32
A3: Social | B3: 30 | C3: =(H27+H42)*(B3/100) -> 2.97
A4: Governance | B4: 30 | C4: =(H48+H55)*(B4/100) -> 2.4
A5: Total | B5: =SUM(B2:B4) -> 100 | C5: =SUM(C2:C4) -> 11.69
A7: Environment | B7: 1 | C7: Management system training (20 Points) | D7: Answers | E7: Responses | F7: Supporting documents | I7: ESG Score (%)
A8: Environment | B8: 1.1 | C8: Does the facility have a management system in place, or is it developing one, to assess environmental risks associated with production? | D8: Yes/No | E8: Yes | G8: =IF(E8="Yes",5,0)+IF(E9="Yes",5,0) -> 10 | H8: =SUM(G8:G17)*(J8/100) -> 8 | I8: 10 | J8: 20
A9: Environment | C9: If yes, Specify certification ? | D9: ISO 14001, RC 14001, or EMAS | E9: Yes | F9: Upload document
A10: Environment | B10: 1.2 | C10: Is the facility management system in compliance with applicable environmental laws and regulations? | D10: Drop down for the same to be provided (Multi select) | F10: Number of ticks/selection | G10: =IF(E10=0,0,IF(E10<3,8,IF(E10<5,15,IF(E10>5,20)))) -> 0 | I10: 20
A11: Environment | B11: 1.3 | C11: Does the facility hold the necessary valid license(s) or permit(s) to operate ? | D11: License(s) or Permit(s): Air emissions Storage or use of hazardous substances Waste water management Waste issues | E11: 3 | F11: Fines, prosecution, or warnings by regulators: Air emissions Storage or use of hazardous substances Preventing soil & groundwater contamination Wastewater management Waste issues | G11: =IF(E11=0,0,IF(E11<3,8,IF(E11<5,15,IF(E11>5,20)))) -> 15 | I11: 20
A12: Environment | B12: 1.3.1 | C12: Has the facility been levied with fines, penalty, warning or prosecution in past ? Specify year and details | D12: Yes/No | E12: Yes | G12: =IF(E12="Yes",0,10) -> 0 | I12: 10
A13: Environment | B13: `1.4 | C13: Are environmental policies, practices, and expectations communicated to all employees and suppliers in local or appropriate languages? | D13: Yes/No Provide proof (Uploads) | E13: No | F13: No | G13: =IF(E13="Yes",5,0)+IF(F13="Yes",5,0) -> 0 | I13: 10
A14: Environment | B14: 1.6 | C14: Do you have a training Awareness Programs of employess for awareness related to Environment? Frequency | D14: Monthly, Quarterly, Half yearly, Annual | E14: Yes | G14: =IF(E14="Yes",5,0)+(IF(F14="Monthly",5,IF(F14="Quarterly",4,IF(F14="Half Yearly",3,IF(F14="Annual",2,0))))) -> 5 | I14: 10
A15: Environment | B15: 1.7 | C15: Does the facility have established environmental targets and objectives to improve environmental performance? | D15: Yes/No | E15: Yes | F15: If Yes, Specify | G15: =IF(E15="Yes",10,0) -> 10 | I15: 10
A16: Environment | B16: 1.8 | C16: Does the facility review its environmental performance? If yes How often | D16: Monthly, Quarterly, Half yearly, Annual | E16: No | G16: =IF(E16="Yes",5,0)+(IF(F16="Monthly",5,IF(F16="Quarterly",4,IF(F16="Half Yearly",3,IF(F16="Annual",2,0))))) -> 0 | I16: 10
A17: Environment
A18: Environment | B18: 2. Greenhouse Gas (GHG) Emissions and Energy Usage
A19: Environment | B19: 2.1 | C19: Does the facility report GHG emissions and climate change strategy to the Carbon Disclosure Project (CDP) or publicly disclose an equivalent amount and type of information on an annual basis? | D19: Yes/No Provide proof (Uploads) | E19: Yes | F19: No | G19: =IF(E19="Yes",15,0)+IF(F19="Yes",15,0) -> 15 | H19: =SUM(G19:G24)*(J19/100) -> 7.8 | I19: 30 | J19: 15
A20: Environment | B20: 2.2 | C20: What is the frequency of monitoring, tracking energy consumption and conducting onsite energy audits of the facility? | D20: Monthly, Quarterly, Half yearly, Annual | F20: Quarterly | G20: =(IF(F20="Monthly",15,IF(F20="Quarterly",12,IF(F20="Half Yearly",9,IF(F20="Annual",6,0))))) -> 12 | I20: 15
A21: Environment | B21: 2.3 | C21: Specify programs and procedures in place to reduce the use of energy | D21: Subjective | F21: Number of ticks/selection | G21: =IF(E21=0,0,IF(E21<3,8,IF(E21<5,15,IF(E21>5,20)))) -> 0 | I21: 20
A22: Environment | B22: 2.4 | C22: Specify the GHG emissions targets for the facility if any ? | D22: Numeric Response | E22: Yes | F22: Numeric entry | G22: =IF(E22="Yes",10,0) -> 10 | I22: 10
A23: Environment | B23: 2.5 | C23: What is the total annual GHG emissions in the most recent year measured (enter in total metric tons CO2e)? | D23: Numeric Response | E23: No | F23: Numeric entry | G23: =IF(E23="Yes",10,0) -> 0 | I23: 10
A24: Environment | B24: 2.6 | C24: Does the facility have set goals and targets in relation to energy efficiency? | D24: Yes/No | E24: Yes | G24: =IF(E24="Yes",15,0) -> 15 | I24: 15
A26: Social | B26: 1 | C26: Employment
A27: Social | B27: 1.1 | C27: Total number of new employees hired in the indicated period. | D27: Numeric response | E27: 5 | F27: Numeric | G27: =IF(E27=0,0,IF(E27<5,6,IF(E27<10,8,IF(E27>10,10)))) -> 8 | H27: =SUM(G27:G40)*(J27/100) -> 5.9 | I27: 10 | J27: 10
A28: Social | B28: 1.2 | C28: Number of new employees females hired for the indicated period | D28: Numeric response | E28: 7 | F28: Numeric | G28: =IF(E28=0,0,IF(E28<5,6,IF(E28<10,8,IF(E28>10,10)))) -> 8 | I28: 10
A29: Social | B29: 1.3 | C29: Number of new employees males hired for the indicated period | D29: Numeric response | E29: 2 | F29: Numeric | G29: =IF(E29=0,0,IF(E29<5,6,IF(E29<10,8,IF(E29>10,10)))) -> 6 | I29: 10
A30: Social | B30: 1.4 | C30: Number of third gender employees hired for the indicated period | D30: Numeric response | E30: 5 | F30: Numeric | G30: =IF(E30=0,0,IF(E30<5,6,IF(E30<10,8,IF(E30>10,10)))) -> 8 | I30: 10
A31: Social | B31: 1.5 | C31: Rate of tunrnover of the employees for the reporting period (Numbers of employees left/ total strength for the period *100) | D31: Numeric response | E31: 6 | G31: =IF(E31=0,0,IF(E31<5,10,IF(E31<10,6,IF(E31>10,2)))) -> 6 | I31: 10
A32: Social | B32: 1.6 | C32: Does Company provides benefits to its full time employees | D32: Yes/No | E32: No | F32: If yes provide proof | G32: =IF(E32="Yes",0,0)+IF(E34="Yes",2,0)+IF(E35="Yes",2,0)+IF(E36="Yes",2,0)+IF(E37="Yes",2,0)+IF(F34="Yes",3,0)+IF(F35="Yes",3,0)+IF(F36="Yes",3,0)+IF(F37="Yes",3,0) -> 5 | I32: 20 (5 each point)
A33: Social | C33: If Yes, Select the options relevant
A34: Social | C34: Health care | D34: Yes/No | E34: Yes | F34: Yes
A35: Social | C35: Life insurance | D35: Yes/No | E35: No | F35: No
A36: Social | C36: Stock ownership | D36: Yes/No | E36: No | F36: No
A37: Social | C37: Parental leave | D37: Yes/No | E37: No | F37: No
A38: Social | B38: 1.7 | C38: Ratio of contractual to non contractual workforce | D38: Numeric response | E38: 4 | G38: =IF(E38=0,0,IF(E38<5,10,IF(E38<10,6,IF(E38>10,2)))) -> 10 | I38: 10
A39: Social | B39: 1.8 | C39: Ratio of permanent employees females to male (time sensitive- yearly information ) | D39: Numeric response | E39: 25 | G39: =IF(E39=0,0,IF(E39<25,2,IF(E39<40,4,IF(E39<55,6,IF(E39<70,8,IF(E39>70,10)))))) -> 4 | I39: 10
A40: Social | B40: 1.9 | C40: Minimum number of weeks’ notice typically provided to employees and their representatives in advance for operational changes | D40: Numeric response | E40: 15 | G40: =IF(E40=0,0,IF(E40<15,2,IF(E40<30,4,IF(E40<45,6,IF(E40<60,8,IF(E40>60,10,)))))) -> 4 | I40: 10
A41: Social | B41: 2 | C41: Child Labour
A42: Social | B42: 2.1 | C42: Does the organisation engage person for work below 18 years of age | D42: Yes/No | E42: Yes | G42: =IF(E42="No",20,0) -> 0 | H42: =SUM(G42:G45)*(J42/100) -> 4 | I42: 20 | J42: 5
A43: Social | B43: 2.2 | C43: Does organisation has any policy against child labour and remediation plan in case anyone found? | D43: Yes/No Upload Policy | E43: Yes | F43: Yes | G43: =IF(E43="Yes",15,0)+IF(F43="Yes",15,0) -> 30 | I43: 30
...

Sheet 4
A2: Environment | B2: 40 | C2: =(H8+H19)*(B2/100) -> 4.8
A3: Social | B3: 30 | C3: =(H27+H42)*(B3/100) -> 1.2
A4: Governance | B4: 30 | C4: =(H48+H55)*(B4/100) -> 4.98
A5: Total | B5: =SUM(B2:B4) -> 100 | C5: =SUM(C2:C4) -> 10.98
A7: Environment | B7: 1 | C7: Management system training (20 Points) | D7: Answers | E7: Responses | F7: Supporting documents | I7: ESG Score (%)
A8: Environment | B8: 1.1 | C8: Does the facility have a management system in place, or is it developing one, to assess environmental risks associated with production? | D8: Yes/No | E8: No | G8: =IF(E8="Yes",5,0)+IF(E9="Yes",5,0) -> 5 | H8: =SUM(G8:G17)*(J8/100) -> 8.4 | I8: 10 | J8: 20
A9: Environment | C9: If yes, Specify certification ? | D9: ISO 14001, RC 14001, or EMAS | E9: Yes | F9: Upload document
A10: Environment | B10: 1.2 | C10: Is the facility management system in compliance with applicable environmental laws and regulations? | D10: Drop down for the same to be provided (Multi select) | F10: Number of ticks/selection | G10: =IF(E10=0,0,IF(E10<3,8,IF(E10<5,15,IF(E10>5,20)))) -> 0 | I10: 20
A11: Environment | B11: 1.3 | C11: Does the facility hold the necessary valid license(s) or permit(s) to operate ? | D11: License(s) or Permit(s): Air emissions Storage or use of hazardous substances Waste water management Waste issues | E11: 6 | F11: Fines, prosecution, or warnings by regulators: Air emissions Storage or use of hazardous substances Preventing soil & groundwater contamination Wastewater management Waste issues | G11: =IF(E11=0,0,IF(E11<3,8,IF(E11<5,15,IF(E11>5,20)))) -> 20 | I11: 20
A12: Environment | B12: 1.3.1 | C12: Has the facility been levied with fines, penalty, warning or prosecution in past ? Specify year and details | D12: Yes/No | E12: Yes | G12: =IF(E12="Yes",0,10) -> 0 | I12: 10
A13: Environment | B13: `1.4 | C13: Are environmental policies, practices, and expectations communicated to all employees and suppliers in local or appropriate languages? | D13: Yes/No Provide proof (Uploads) | E13: Yes | F13: No | G13: =IF(E13="Yes",5,0)+IF(F13="Yes",5,0) -> 5 | I13: 10
A14: Environment | B14: 1.6 | C14: Do you have a training Awareness Programs of employess for awareness related to Environment? Frequency | D14: Monthly, Quarterly, Half yearly, Annual | E14: No | F14: Half Yearly | G14: =IF(E14="Yes",5,0)+(IF(F14="Monthly",5,IF(F14="Quarterly",4,IF(F14="Half Yearly",3,IF(F14="Annual",2,0))))) -> 3 | I14: 10
A15: Environment | B15: 1.7 | C15: Does the facility have established environmental targets and objectives to improve environmental performance? | D15: Yes/No | E15: No | F15: If Yes, Specify | G15: =IF(E15="Yes",10,0) -> 0 | I15: 10
A16: Environment | B16: 1.8 | C16: Does the facility review its environmental performance? If yes How often | D16: Monthly, Quarterly, Half yearly, Annual | E16: Yes | F16: Quarterly | G16: =IF(E16="Yes",5,0)+(IF(F16="Monthly",5,IF(F16="Quarterly",4,IF(F16="Half Yearly",3,IF(F16="Annual",2,0))))) -> 9 | I16: 10
A17: Environment
A18: Environment | B18: 2. Greenhouse Gas (GHG) Emissions and Energy Usage
A19: Environment | B19: 2.1 | C19: Does the facility report GHG emissions and climate change strategy to the Carbon Disclosure Project (CDP) or publicly disclose an equivalent amount and type of information on an annual basis? | D19: Yes/No Provide proof (Uploads) | E19: No | F19: No | G19: =IF(E19="Yes",15,0)+IF(F19="Yes",15,0) -> 0 | H19: =SUM(G19:G24)*(J19/100) -> 3.6 | I19: 30 | J19: 15
A20: Environment | B20: 2.2 | C20: What is the frequency of monitoring, tracking energy consumption and conducting onsite energy audits of the facility? | D20: Monthly, Quarterly, Half yearly, Annual | F20: Half Yearly | G20: =(IF(F20="Monthly",15,IF(F20="Quarterly",12,IF(F20="Half Yearly",9,IF(F20="Annual",6,0))))) -> 9 | I20: 15
A21: Environment | B21: 2.3 | C21: Specify programs and procedures in place to reduce the use of energy | D21: Subjective | F21: Number of ticks/selection | G21: =IF(E21=0,0,IF(E21<3,8,IF(E21<5,15,IF(E21>5,20)))) -> 0 | I21: 20
A22: Environment | B22: 2.4 | C22: Specify the GHG emissions targets for the facility if any ? | D22: Numeric Response | E22: No | F22: Numeric entry | G22: =IF(E22="Yes",10,0) -> 0 | I22: 10
A23: Environment | B23: 2.5 | C23: What is the total annual GHG emissions in the most recent year measured (enter in total metric tons CO2e)? | D23: Numeric Response | E23: No | F23: Numeric entry | G23: =IF(E23="Yes",10,0) -> 0 | I23: 10
A24: Environment | B24: 2.6 | C24: Does the facility have set goals and targets in relation to energy efficiency? | D24: Yes/No | E24: Yes | G24: =IF(E24="Yes",15,0) -> 15 | I24: 15
A26: Social | B26: 1 | C26: Employment
A27: Social | B27: 1.1 | C27: Total number of new employees hired in the indicated period. | D27: Numeric response | E27: 15 | F27: Numeric | G27: =IF(E27=0,0,IF(E27<5,6,IF(E27<10,8,IF(E27>10,10)))) -> 10 | H27: =SUM(G27:G40)*(J27/100) -> 4 | I27: 10 | J27: 10
A28: Social | B28: 1.2 | C28: Number of new employees females hired for the indicated period | D28: Numeric response | E28: 7 | F28: Numeric | G28: =IF(E28=0,0,IF(E28<5,6,IF(E28<10,8,IF(E28>10,10)))) -> 8 | I28: 10
A29: Social | B29: 1.3 | C29: Number of new employees males hired for the indicated period | D29: Numeric response | E29: 5 | F29: Numeric | G29: =IF(E29=0,0,IF(E29<5,6,IF(E29<10,8,IF(E29>10,10)))) -> 8 | I29: 10
A30: Social | B30: 1.4 | C30: Number of third gender employees hired for the indicated period | D30: Numeric response | E30: 0 | F30: Numeric | G30: =IF(E30=0,0,IF(E30<5,6,IF(E30<10,8,IF(E30>10,10)))) -> 0 | I30: 10
A31: Social | B31: 1.5 | C31: Rate of tunrnover of the employees for the reporting period (Numbers of employees left/ total strength for the period *100) | D31: Numeric response | E31: 50 | G31: =IF(E31=0,0,IF(E31<5,10,IF(E31<10,6,IF(E31>10,2)))) -> 2 | I31: 10
A32: Social | B32: 1.6 | C32: Does Company provides benefits to its full time employees | D32: Yes/No | E32: Yes | F32: If yes provide proof | G32: =IF(E32="Yes",0,0)+IF(E34="Yes",2,0)+IF(E35="Yes",2,0)+IF(E36="Yes",2,0)+IF(E37="Yes",2,0)+IF(F34="Yes",3,0)+IF(F35="Yes",3,0)+IF(F36="Yes",3,0)+IF(F37="Yes",3,0) -> 0 | I32: 20 (5 each point)
A33: Social | C33: If Yes, Select the options relevant
A34: Social | C34: Health care | D34: Yes/No | E34: No | F34: No
A35: Social | C35: Life insurance | D35: Yes/No | E35: No | F35: No
A36: Social | C36: Stock ownership | D36: Yes/No | E36: No | F36: No
A37: Social | C37: Parental leave | D37: Yes/No | E37: No | F37: No
A38: Social | B38: 1.7 | C38: Ratio of contractual to non contractual workforce | D38: Numeric response | E38: 0 | G38: =IF(E38=0,0,IF(E38<5,10,IF(E38<10,6,IF(E38>10,2)))) -> 0 | I38: 10
A39: Social | B39: 1.8 | C39: Ratio of permanent employees females to male (time sensitive- yearly information ) | D39: Numeric response | E39: 40 | G39: =IF(E39=0,0,IF(E39<25,2,IF(E39<40,4,IF(E39<55,6,IF(E39<70,8,IF(E39>70,10)))))) -> 6 | I39: 10
A40: Social | B40: 1.9 | C40: Minimum number of weeks’ notice typically provided to employees and their representatives in advance for operational changes | D40: Numeric response | E40: 30 | G40: =IF(E40=0,0,IF(E40<15,2,IF(E40<30,4,IF(E40<45,6,IF(E40<60,8,IF(E40>60,10,)))))) -> 6 | I40: 10
A41: Social | B41: 2 | C41: Child Labour
A42: Social | B42: 2.1 | C42: Does the organisation engage person for work below 18 years of age | D42: Yes/No | E42: Yes | G42: =IF(E42="No",20,0) -> 0 | H42: =SUM(G42:G45)*(J42/100) -> 0 | I42: 20 | J42: 5
A43: Social | B43: 2.2 | C43: Does organisation has any policy against child labour and remediation plan in case anyone found? | D43: Yes/No Upload Policy | E43: No | F43: No | G43: =IF(E43="Yes",15,0)+IF(F43="Yes",15,0) -> 0 | I43: 30
...

Sheet 5
A2: Environment | B2: 40 | C2: =(H8+H19)*(B2/100) -> 14
A3: Social | B3: 30 | C3: =(H27+H42)*(B3/100) -> 4.5
A4: Governance | B4: 30 | C4: =(H48+H55)*(B4/100) -> 12
A5: Total | B5: =SUM(B2:B4) -> 100 | C5: =SUM(C2:C4) -> 30.5
A7: Environment | B7: 1 | C7: Management system training (20 Points) | D7: Answers | E7: Responses | F7: Supporting documents | I7: ESG Score (%)
A8: Environment | B8: 1.1 | C8: Does the facility have a management system in place, or is it developing one, to assess environmental risks associated with production? | D8: Yes/No | E8: Yes | G8: =IF(E8="Yes",5,0)+IF(E9="Yes",5,0) -> 10 | H8: =SUM(G8:G17)*(J8/100) -> 20 | I8: 10 | J8: 20
A9: Environment | C9: If yes, Specify certification ? | D9: ISO 14001, RC 14001, or EMAS | E9: Yes | F9: Upload document
A10: Environment | B10: 1.2 | C10: Is the facility management system in compliance with applicable environmental laws and regulations? | D10: Drop down for the same to be provided (Multi select) | E10: g | F10: Number of ticks/selection | G10: =IF(E10=0,0,IF(E10<3,8,IF(E10<5,15,IF(E10>5,20)))) -> 20 | I10: 20
A11: Environment | B11: 1.3 | C11: Does the facility hold the necessary valid license(s) or permit(s) to operate ? | D11: License(s) or Permit(s): Air emissions Storage or use of hazardous substances Waste water management Waste issues | E11: 6 | F11: Fines, prosecution, or warnings by regulators: Air emissions Storage or use of hazardous substances Preventing soil & groundwater contamination Wastewater management Waste issues | G11: =IF(E11=0,0,IF(E11<3,8,IF(E11<5,15,IF(E11>5,20)))) -> 20 | I11: 20
A12: Environment | B12: 1.3.1 | C12: Has the facility been levied with fines, penalty, warning or prosecution in past ? Specify year and details | D12: Yes/No | E12: No | G12: =IF(E12="Yes",0,10) -> 10 | I12: 10
A13: Environment | B13: `1.4 | C13: Are environmental policies, practices, and expectations communicated to all employees and suppliers in local or appropriate languages? | D13: Yes/No Provide proof (Uploads) | E13: Yes | F13: Yes | G13: =IF(E13="Yes",5,0)+IF(F13="Yes",5,0) -> 10 | I13: 10
A14: Environment | B14: 1.6 | C14: Do you have a training Awareness Programs of employess for awareness related to Environment? Frequency | D14: Monthly, Quarterly, Half yearly, Annual | E14: Yes | F14: Monthly | G14: =IF(E14="Yes",5,0)+(IF(F14="Monthly",5,IF(F14="Quarterly",4,IF(F14="Half Yearly",3,IF(F14="Annual",2,0))))) -> 10 | I14: 10
A15: Environment | B15: 1.7 | C15: Does the facility have established environmental targets and objectives to improve environmental performance? | D15: Yes/No | E15: Yes | F15: If Yes, Specify | G15: =IF(E15="Yes",10,0) -> 10 | I15: 10
A16: Environment | B16: 1.8 | C16: Does the facility review its environmental performance? If yes How often | D16: Monthly, Quarterly, Half yearly, Annual | E16: Yes | F16: Monthly | G16: =IF(E16="Yes",5,0)+(IF(F16="Monthly",5,IF(F16="Quarterly",4,IF(F16="Half Yearly",3,IF(F16="Annual",2,0))))) -> 10 | I16: 10
A17: Environment
A18: Environment | B18: 2. Greenhouse Gas (GHG) Emissions and Energy Usage
A19: Environment | B19: 2.1 | C19: Does the facility report GHG emissions and climate change strategy to the Carbon Disclosure Project (CDP) or publicly disclose an equivalent amount and type of information on an annual basis? | D19: Yes/No Provide proof (Uploads) | E19: Yes | F19: Yes | G19: =IF(E19="Yes",15,0)+IF(F19="Yes",15,0) -> 30 | H19: =SUM(G19:G24)*(J19/100) -> 15 | I19: 30 | J19: 15
A20: Environment | B20: 2.2 | C20: What is the frequency of monitoring, tracking energy consumption and conducting onsite energy audits of the facility? | D20: Monthly, Quarterly, Half yearly, Annual | F20: Monthly | G20: =(IF(F20="Monthly",15,IF(F20="Quarterly",12,IF(F20="Half Yearly",9,IF(F20="Annual",6,0))))) -> 15 | I20: 15
A21: Environment | B21: 2.3 | C21: Specify programs and procedures in place to reduce the use of energy | D21: Subjective | E21: t | F21: Number of ticks/selection | G21: =IF(E21=0,0,IF(E21<3,8,IF(E21<5,15,IF(E21>5,20)))) -> 20 | I21: 20
A22: Environment | B22: 2.4 | C22: Specify the GHG emissions targets for the facility if any ? | D22: Numeric Response | E22: Yes | F22: Numeric entry | G22: =IF(E22="Yes",10,0) -> 10 | I22: 10
A23: Environment | B23: 2.5 | C23: What is the total annual GHG emissions in the most recent year measured (enter in total metric tons CO2e)? | D23: Numeric Response | E23: Yes | F23: Numeric entry | G23: =IF(E23="Yes",10,0) -> 10 | I23: 10
A24: Environment | B24: 2.6 | C24: Does the facility have set goals and targets in relation to energy efficiency? | D24: Yes/No | E24: Yes | G24: =IF(E24="Yes",15,0) -> 15 | I24: 15
A26: Social | B26: 1 | C26: Employment
A27: Social | B27: 1.1 | C27: Total number of new employees hired in the indicated period. | D27: Numeric response | E27: 20 | F27: Numeric | G27: =IF(E27=0,0,IF(E27<5,6,IF(E27<10,8,IF(E27>10,10)))) -> 10 | H27: =SUM(G27:G40)*(J27/100) -> 10 | I27: 10 | J27: 10
A28: Social | B28: 1.2 | C28: Number of new employees females hired for the indicated period | D28: Numeric response | E28: 15 | F28: Numeric | G28: =IF(E28=0,0,IF(E28<5,6,IF(E28<10,8,IF(E28>10,10)))) -> 10 | I28: 10
A29: Social | B29: 1.3 | C29: Number of new employees males hired for the indicated period | D29: Numeric response | E29: 11 | F29: Numeric | G29: =IF(E29=0,0,IF(E29<5,6,IF(E29<10,8,IF(E29>10,10)))) -> 10 | I29: 10
A30: Social | B30: 1.4 | C30: Number of third gender employees hired for the indicated period | D30: Numeric response | E30: 11 | F30: Numeric | G30: =IF(E30=0,0,IF(E30<5,6,IF(E30<10,8,IF(E30>10,10)))) -> 10 | I30: 10
A31: Social | B31: 1.5 | C31: Rate of tunrnover of the employees for the reporting period (Numbers of employees left/ total strength for the period *100) | D31: Numeric response | E31: 1 | G31: =IF(E31=0,0,IF(E31<5,10,IF(E31<10,6,IF(E31>10,2)))) -> 10 | I31: 10
A32: Social | B32: 1.6 | C32: Does Company provides benefits to its full time employees | D32: Yes/No | E32: Yes | F32: If yes provide proof | G32: =IF(E32="Yes",0,0)+IF(E34="Yes",2,0)+IF(E35="Yes",2,0)+IF(E36="Yes",2,0)+IF(E37="Yes",2,0)+IF(F34="Yes",3,0)+IF(F35="Yes",3,0)+IF(F36="Yes",3,0)+IF(F37="Yes",3,0) -> 20 | I32: 20 (5 each point)
A33: Social | C33: If Yes, Select the options relevant
A34: Social | C34: Health care | D34: Yes/No | E34: Yes | F34: Yes
A35: Social | C35: Life insurance | D35: Yes/No | E35: Yes | F35: Yes
A36: Social | C36: Stock ownership | D36: Yes/No | E36: Yes | F36: Yes
A37: Social | C37: Parental leave | D37: Yes/No | E37: Yes | F37: Yes
A38: Social | B38: 1.7 | C38: Ratio of contractual to non contractual workforce | D38: Numeric response | E38: 1 | G38: =IF(E38=0,0,IF(E38<5,10,IF(E38<10,6,IF(E38>10,2)))) -> 10 | I38: 10
A39: Social | B39: 1.8 | C39: Ratio of permanent employees females to male (time sensitive- yearly information ) | D39: Numeric response | E39: 80 | G39: =IF(E39=0,0,IF(E39<25,2,IF(E39<40,4,IF(E39<55,6,IF(E39<70,8,IF(E39>70,10)))))) -> 10 | I39: 10
A40: Social | B40: 1.9 | C40: Minimum number of weeks’ notice typically provided to employees and their representatives in advance for operational changes | D40: Numeric response | E40: 65 | G40: =IF(E40=0,0,IF(E40<15,2,IF(E40<30,4,IF(E40<45,6,IF(E40<60,8,IF(E40>60,10,)))))) -> 10 | I40: 10
A41: Social | B41: 2 | C41: Child Labour
A42: Social | B42: 2.1 | C42: Does the organisation engage person for work below 18 years of age | D42: Yes/No | E42: No | G42: =IF(E42="No",20,0) -> 20 | H42: =SUM(G42:G45)*(J42/100) -> 5 | I42: 20 | J42: 5
A43: Social | B43: 2.2 | C43: Does organisation has any policy against child labour and remediation plan in case anyone found? | D43: Yes/No Upload Policy | E43: Yes | F43: Yes | G43: =IF(E43="Yes",15,0)+IF(F43="Yes",15,0) -> 30 | I43: 30
...
